<sdf version='1.7'>
  <model name='etrobo_spike'>
    <link name='base_footprint'>
      <inertial>
        <pose>-0.051961 0 0.10902 0 -0 0</pose>
        <mass>5.1</mass>
        <inertia>
          <ixx>0.0422461</ixx>
          <ixy>0</ixy>
          <ixz>-0.000490196</ixz>
          <iyy>0.0432265</iyy>
          <iyz>0</iyz>
          <izz>0.0759814</izz>
        </inertia>
      </inertial>
      <collision name='base_footprint_fixed_joint_lump__base_link_collision'>
        <pose>-0.05 0 0.11 0 -0 0</pose>
        <geometry>
          <box>
            <size>0.3 0.3 0.1</size>
          </box>
        </geometry>
      </collision>
      <collision name='base_footprint_fixed_joint_lump__caster_back_link_collision_1'>
        <pose>-0.15 0 0.06 0 -0 0</pose>
        <geometry>
          <sphere>
            <radius>0.05</radius>
          </sphere>
        </geometry>
      </collision>
      <visual name='base_footprint_fixed_joint_lump__base_link_visual'>
        <pose>-0.05 0 0.11 0 -0 0</pose>
        <geometry>
          <box>
            <size>0.3 0.3 0.1</size>
          </box>
        </geometry>
      </visual>
      <visual name='base_footprint_fixed_joint_lump__caster_back_link_visual_1'>
        <pose>-0.15 0 0.06 0 -0 0</pose>
        <geometry>
          <sphere>
            <radius>0.05</radius>
          </sphere>
        </geometry>
      </visual>
    </link>
    <joint name='wheel_left_joint' type='revolute'>
      <pose relative_to='base_footprint'>0 0 0.01 0 -0 0</pose>
      <parent>base_footprint</parent>
      <child>wheel_left_link</child>
      <axis>
        <xyz>0 1 0</xyz>
        <limit>
          <lower>-1e+16</lower>
          <upper>1e+16</upper>
        </limit>
        <dynamics>
          <spring_reference>0</spring_reference>
          <spring_stiffness>0</spring_stiffness>
        </dynamics>
      </axis>
    </joint>
    <link name='wheel_left_link'>
      <pose relative_to='wheel_left_joint'>0 0 0 0 -0 0</pose>
      <inertial>
        <pose>0 0.18 0.072 1.5707 -0 0</pose>
        <mass>0.2</mass>
        <inertia>
          <ixx>0.00026</ixx>
          <ixy>0</ixy>
          <ixz>0</ixz>
          <iyy>0.00026</iyy>
          <iyz>0</iyz>
          <izz>0.00052</izz>
        </inertia>
      </inertial>
      <collision name='wheel_left_link_collision'>
        <pose>0 0.18 0.072 1.5707 -0 0</pose>
        <geometry>
          <cylinder>
            <length>0.04</length>
            <radius>0.072</radius>
          </cylinder>
        </geometry>
      </collision>
      <visual name='wheel_left_link_visual'>
        <pose>0 0.18 0.072 1.5707 -0 0</pose>
        <geometry>
          <cylinder>
            <length>0.04</length>
            <radius>0.072</radius>
          </cylinder>
        </geometry>
      </visual>
    </link>
    <joint name='wheel_right_joint' type='revolute'>
      <pose relative_to='base_footprint'>0 0 0.01 0 -0 0</pose>
      <parent>base_footprint</parent>
      <child>wheel_right_link</child>
      <axis>
        <xyz>0 1 0</xyz>
        <limit>
          <lower>-1e+16</lower>
          <upper>1e+16</upper>
        </limit>
        <dynamics>
          <spring_reference>0</spring_reference>
          <spring_stiffness>0</spring_stiffness>
        </dynamics>
      </axis>
    </joint>
    <link name='wheel_right_link'>
      <pose relative_to='wheel_right_joint'>0 0 0 0 -0 0</pose>
      <inertial>
        <pose>0 -0.18 0.072 1.5707 -0 0</pose>
        <mass>0.2</mass>
        <inertia>
          <ixx>0.00026</ixx>
          <ixy>0</ixy>
          <ixz>0</ixz>
          <iyy>0.00026</iyy>
          <iyz>0</iyz>
          <izz>0.00052</izz>
        </inertia>
      </inertial>
      <collision name='wheel_right_link_collision'>
        <pose>0 -0.18 0.072 1.5707 -0 0</pose>
        <geometry>
          <cylinder>
            <length>0.04</length>
            <radius>0.072</radius>
          </cylinder>
        </geometry>
      </collision>
      <visual name='wheel_right_link_visual'>
        <pose>0 -0.18 0.072 1.5707 -0 0</pose>
        <geometry>
          <cylinder>
            <length>0.04</length>
            <radius>0.072</radius>
          </cylinder>
        </geometry>
      </visual>
    </link>
  </model>
</sdf>
