<?xml version='1.0'?>
<sdf version="1.6">
  <model name="etrobo_spike">
    <pose>0.0 0.0 0.0 0.0 0.0 0.0</pose>

    <link name="base_footprint"/>

    <joint name="base_joint" type="fixed">
      <parent>base_footprint</parent>
      <child>body_link</child>
      <pose>0.0 0.0 0.083853 0 0 0</pose>
    </joint>

    <link name="body_link">
      <inertial>
        <pose>-0.0168 0 0.0704 0 0.927295177 0</pose>
        <mass>0.434</mass>
        <inertia>
          <ixx>0.0006538</ixx>
          <ixy>0.0</ixy>
          <ixz>0.0001067</ixz>
          <iyy>0.0006851</iyy>
          <iyz>0.0</iyz>
          <izz>0.0005915</izz>
        </inertia>
      </inertial>

      <collision name="base_collision">
        <pose>-0.0168 0 0.0704 0 0.927295177 0</pose>
        <geometry>
          <box>
            <size>0.112 0.088 0.08</size>
          </box>
        </geometry>
      </collision>

      <!--
      <visual name="base_visual">
        <pose>-0.0168 0 0.0704 0 0.927295177 0</pose>
        <geometry>
          <box>
            <size>0.112 0.088 0.08</size>
          </box>
        </geometry>
        <material>
          <script>
            <name>Gazebo/Turquoise</name>
          </script>
        </material>
      </visual>
      -->
      <visual name="base_visual">
        <pose>0 0 0 0 0 0</pose>
        <geometry>
          <mesh>
            <uri>model://etrobo_spike/meshes/HackSPi.dae</uri>
          </mesh>
        </geometry>
        <material>
          <ambient>0.777 0.0088 0.802 1</ambient>
          <diffuse>0.777 0.0088 0.802 1</diffuse>
        </material>
      </visual>

    </link>

    <joint name="wheel_left_joint" type="revolute">
      <parent>body_link</parent>
      <child>wheel_left_link</child>
      <pose>0 0.056 0.028 0 0 0</pose>
      <axis>
        <xyz>0 1 0</xyz>
        <limit>
          <velocity>19.4</velocity>    <!-- rad/s -->
          <effort>0.18</effort>        <!-- = max_wheel_torque  (N·m) -->
        </limit>
      </axis>
    </joint>

    <link name="wheel_left_link">
      <inertial>
        <pose>0 0.056 0.028 1.5707 0 0</pose>
        <mass>0.014</mass>
        <inertia>
          <ixx>2.82e-6</ixx>
          <ixy>0.0</ixy>
          <ixz>0.0</ixz>
          <iyy>2.82e-6</iyy>
          <iyz>0.0</iyz>
          <izz>5.49e-6</izz>
        </inertia>
      </inertial>

      <collision name="collision">
        <pose>0 0.056 0.028 1.5707 0 0</pose>
        <geometry>
          <cylinder>
            <radius>0.028</radius>
            <length>0.008</length>
          </cylinder>
        </geometry>
        <surface>
          <friction>
            <ode>
              <mu>0.5</mu>
              <mu2>0.5</mu2>
            </ode>
          </friction>
          <contact>
            <ode>
              <kp>100000</kp>
              <kd>1</kd>
            </ode>
          </contact>
        </surface>
      </collision>

      <!--
      <visual name="visual">
        <pose>0 0.056 0.028 1.5707 0 0</pose>
        <geometry>
          <cylinder>
            <radius>0.028</radius>
            <length>0.008</length>
          </cylinder>
        </geometry>
        <material>
          <script>
            <name>Gazebo/Red</name>
          </script>
        </material>
      </visual>
      -->
    </link>

    <joint name="wheel_right_joint" type="revolute">
      <parent>body_link</parent>
      <child>wheel_right_link</child>
      <pose>0 -0.056 0.028 0 0 0</pose>
      <axis>
        <xyz>0 1 0</xyz>
        <limit>
          <velocity>19.4</velocity>    <!-- rad/s -->
          <effort>0.18</effort>        <!-- = max_wheel_torque  (N·m) -->
        </limit>
      </axis>
    </joint>

    <link name="wheel_right_link">
      <inertial>
        <pose>0 -0.056 0.028 1.5707 0 0</pose>
        <mass>0.1</mass>
        <inertia>
          <ixx>2.82e-6</ixx>
          <ixy>0.0</ixy>
          <ixz>0.0</ixz>
          <iyy>2.82e-6</iyy>
          <iyz>0.0</iyz>
          <izz>5.49e-6</izz>
        </inertia>
      </inertial>

      <collision name="collision">
        <pose>0 -0.056 0.028 1.5707 0 0</pose>
        <geometry>
          <cylinder>
            <radius>0.028</radius>
            <length>0.008</length>
          </cylinder>
        </geometry>
        <surface>
          <friction>
            <ode>
              <mu>0.5</mu>
              <mu2>0.5</mu2>
            </ode>
          </friction>
          <contact>
            <ode>
              <kp>100000</kp>
              <kd>1</kd>
            </ode>
          </contact>
        </surface>
      </collision>

      <!--
      <visual name="visual">
        <pose>0 -0.056 0.028 1.5707 0 0</pose>
        <geometry>
          <cylinder>
            <radius>0.028</radius>
            <length>0.008</length>
          </cylinder>
        </geometry>
        <material>
          <script>
            <name>Gazebo/Red</name>
          </script>
        </material>
      </visual>
      -->
    </link>

    <joint name="container_joint" type="fixed">
      <parent>body_link</parent>
      <child>container_link</child>
      <pose>0 0 0 0 0 0</pose>
    </joint>

    <link name="container_link">
      <inertial>
        <pose>-0.1224 0 0.0712 0 0 0</pose>
        <mass>0.354</mass>
        <inertia>
          <ixx>0.000548</ixx>
          <ixy>0.0</ixy>
          <ixz>0.0</ixz>
          <iyy>0.000500</iyy>
          <iyz>0.0</iyz>
          <izz>0.000591</izz>
        </inertia>
      </inertial>

      <collision name="container_collision">
        <pose>-0.1224 0 0.0712 0 0 0</pose>
        <geometry>
          <box>
            <size>0.096 0.104 0.088</size>
          </box>
        </geometry>
      </collision>

      <!--
      <visual name="container_visual">
        <pose>-0.1224 0 0.0712 0 0 0</pose>
        <geometry>
          <box>
            <size>0.096 0.104 0.088</size>
          </box>
        </geometry>
        <material>
          <script>
            <name>Gazebo/Turquoise</name>
          </script>
        </material>
      </visual>
      -->
    </link>

    <joint name="caster_back_joint" type="fixed">
      <parent>container_link</parent>
      <child>caster_back_link</child>
      <pose>-0.021348 0 -0.055228</pose>
    </joint>

    <link name="caster_back_link">
      <inertial>
        <pose>-0.1424 0 0.0152 0 0 0</pose>
        <mass>0.0096</mass>
        <inertia>
          <ixx>5.53e-07</ixx>
          <ixy>0.0</ixy>
          <ixz>0.0</ixz>
          <iyy>5.53e-07</iyy>
          <iyz>0.0</iyz>
          <izz>5.53e-07</izz>
        </inertia>
      </inertial>

      <collision name="collision">
        <pose>-0.1424 0 0.0152 0 0 0</pose>
        <geometry>
          <sphere>
            <radius>0.012</radius>
          </sphere>
        </geometry>
        <surface>
          <friction>
            <ode>
              <mu>0.01</mu>
              <mu2>0.01</mu2>
            </ode>
          </friction>
          <contact>
            <ode>
              <kp>100000</kp>
              <kd>1</kd>
            </ode>
          </contact>
        </surface>
      </collision>

      <!--
      <visual name="visual">
        <pose>-0.1424 0 0.0152 0 0 0</pose>
        <geometry>
          <sphere>
            <radius>0.012</radius>
          </sphere>
        </geometry>
      </visual>
      -->
    </link>

    <joint name="head_joint" type="fixed">
      <parent>body_link</parent>
      <child>head_link</child>
      <pose>0 0 0 0 0 0</pose>
    </joint>

    <link name="head_link">
      <inertial>
        <pose>-0.020 0 0.168 0 0 0</pose>
        <mass>0.124</mass>
        <inertia>
          <ixx>9.59e-05</ixx>
          <ixy>0.0</ixy>
          <ixz>0.0</ixz>
          <iyy>1.08e-04</iyy>
          <iyz>0.0</iyz>
          <izz>1.20e-04</izz>
        </inertia>
      </inertial>

      <collision name="head_collision">
        <pose>-0.020 0 0.168 0 0 0</pose>
        <geometry>
          <box>
            <size>0.080 0.072 0.064</size>
          </box>
        </geometry>
      </collision>

      <!--
      <visual name="head_visual">
        <pose>-0.020 0 0.168 0 0 0</pose>
        <geometry>
          <box>
            <size>0.080 0.072 0.064</size>
          </box>
        </geometry>
        <material>
          <script>
            <name>Gazebo/Turquoise</name>
          </script>
        </material>
      </visual>
      -->

      <!-- New RGB camera on top of body_link -->
      <sensor name="camera_top" type="camera">
        <pose>-0.020 0 0.2 0 0.523598776 0</pose>
        <always_on>1</always_on>
        <visualize>false</visualize>
        <update_rate>30</update_rate>
        <camera>
          <horizontal_fov>1.0471975512</horizontal_fov><!-- 60 degrees -->
          <image>
            <width>640</width>
            <height>480</height>
            <format>R8G8B8</format>
          </image>
          <clip>
            <near>0.1</near>
            <far>10</far>
          </clip>
        </camera>
        <plugin name="gazebo_ros_camera" filename="libgazebo_ros_camera.so">
          <ros>
            <namespace>/camera_top</namespace>
            <remapping>image_raw:=image_raw</remapping>
            <remapping>camera_info:=camera_info</remapping>
          </ros>
          <frame_name>camera_top_link</frame_name>
        </plugin>
      </sensor>
    </link>

    <joint name="arm_joint" type="fixed">
      <parent>body_link</parent>
      <child>arm_link</child>
      <pose>0 0 0 0 0 0</pose>
    </joint>

    <link name="arm_link">
      <inertial>
        <pose>0.040 0 0.032 0 0 0</pose>
        <mass>0.031</mass>
        <inertia>
          <ixx>1.41e-05</ixx>
          <ixy>0.0</ixy>
          <ixz>0.0</ixz>
          <iyy>7.44e-06</iyy>
          <iyz>0.0</iyz>
          <izz>9.59e-06</izz>
        </inertia>
      </inertial>

      <collision name="arm_collision">
        <pose>0.040 0 0.032 0 0 0</pose>
        <geometry>
          <box>
            <size>0.024  0.056 0.048</size>
          </box>
        </geometry>
      </collision>

      <!--
      <visual name="arm_visual">
        <pose>0.040 0 0.032 0 0 0</pose>
        <geometry>
          <box>
            <size>0.024  0.056 0.048</size>
          </box>
        </geometry>
        <material>
          <script>
            <name>Gazebo/Turquoise</name>
          </script>
        </material>
      </visual>
      -->

      <!-- Color sensor (downward facing, front) -->
      <sensor name="color_sensor" type="camera">
        <pose>0.040 0 0.008 0 1.570796327 0</pose>
        <always_on>1</always_on>
        <visualize>false</visualize>
        <update_rate>100</update_rate>
        <camera>
          <horizontal_fov>0.01</horizontal_fov>
          <image>
            <width>16</width>
            <height>16</height>
            <format>R8G8B8</format>
          </image>
          <clip>
            <near>0.004</near>
            <far>0.012</far>
          </clip>
        </camera>
        <!--plugin name="gazebo_ros_camera" filename="libgazebo_ros_camera.so">
          <ros>
          <namespace>/</namespace>
          <remapping>image_raw:=color_sensor/image_raw</remapping>
          <remapping>camera_info:=color_sensor/camera_info</remapping>
          </ros>
          <frame_name>color_sensor_link</frame_name>
        </plugin-->
        <plugin name="gazebo_ros_color_sensor" filename="libgazebo_ros_color_sensor.so">
          <ros>
            <namespace>/color_sensor</namespace>
            <remapping>color:=color</remapping>
          </ros>
        </plugin>
      </sensor>
    </link>

    <plugin name="differential_drive_controller" filename="libgazebo_ros_diff_drive.so">
      <update_rate>100</update_rate>
      <left_joint>wheel_left_joint</left_joint>
      <right_joint>wheel_right_joint</right_joint>
      <wheel_separation>0.112</wheel_separation>
      <wheel_diameter>0.056</wheel_diameter>
      <max_wheel_torque>0.18</max_wheel_torque>
      <max_wheel_acceleration>30</max_wheel_acceleration>
      <publish_odom>true</publish_odom>
      <publish_odom_tf>true</publish_odom_tf>
      <publish_wheel_tf>false</publish_wheel_tf>
      <command_topic>cmd_vel</command_topic>
      <odometry_topic>odom</odometry_topic>
      <odometry_frame>odom</odometry_frame>
      <robot_base_frame>base_footprint</robot_base_frame>
    </plugin>

    <plugin name="turtlebot3_joint_state" filename="libgazebo_ros_joint_state_publisher.so">
      <ros>
        <remapping>~/out:=joint_states</remapping>
      </ros>
      <update_rate>30</update_rate>
      <joint_name>wheel_left_joint</joint_name>
      <joint_name>wheel_right_joint</joint_name>
    </plugin>
  </model>
</sdf>

