<?xml version='1.0'?>
<sdf version="1.6">
  <model name="etrobo_spike">
    <pose>0.0 0.0 0.0 0.0 0.0 0.0</pose>

    <link name="base_footprint"/>

    <joint name="base_joint" type="fixed">
      <parent>base_footprint</parent>
      <child>base_link</child>
      <pose>0.0 0.0 0.08 0 0 0</pose>
    </joint>

    <link name="base_link">
      <inertial>
        <pose>-0.05 0 0.1 0 0 0</pose>
        <mass>5.0</mass>
        <inertia>
          <ixx>0.042</ixx>
          <ixy>0.0</ixy>
          <ixz>0.0</ixz>
          <iyy>0.042</iyy>
          <iyz>0.0</iyz>
          <izz>0.075</izz>
        </inertia>
      </inertial>

      <collision name="base_collision">
        <pose>-0.05 0 0.1 0 0 0</pose>
        <geometry>
          <box>
            <size>0.3 0.3 0.1</size>
          </box>
        </geometry>
      </collision>

      <visual name="base_visual">
        <pose>-0.05 0 0.1 0 0 0</pose>
        <geometry>
          <box>
            <size>0.3 0.3 0.1</size>
          </box>
        </geometry>
      </visual>

      <!-- Color sensor (downward facing, front) -->
      <sensor name="color_sensor" type="camera">
        <pose>0.13 0 0.01 0 1.570796327 0</pose> <!-- X:前方 Y:中央 Z:地面から2.1cm下向き、RPY:Y軸下向き -->
        <always_on>1</always_on>
        <visualize>false</visualize>
        <update_rate>100</update_rate>
        <camera>
          <horizontal_fov>0.01</horizontal_fov>
          <image>
            <width>15</width>
            <height>15</height>
            <format>R8G8B8</format>
          </image>
          <clip>
            <near>0.008</near>
            <far>0.30</far>
          </clip>
        </camera>
        <plugin name="gazebo_ros_color_sensor" filename="libgazebo_ros_camera.so">
          <ros>
            <namespace>/</namespace>
            <remapping>image_raw:=color_sensor/image_raw</remapping>
            <remapping>camera_info:=color_sensor/camera_info</remapping>
          </ros>
          <frame_name>color_sensor_link</frame_name>
        </plugin>
      </sensor>
    </link>

    <joint name="wheel_left_joint" type="revolute">
      <parent>base_link</parent>
      <child>wheel_left_link</child>
      <pose>0 0.18 0.072 0 0 0</pose>
      <axis>
        <xyz>0 1 0</xyz>
      </axis>
    </joint>

    <link name="wheel_left_link">
      <inertial>
        <pose>0 0.18 0.072 1.5707 0 0</pose>
        <mass>0.2</mass>
        <inertia>
          <ixx>0.00026</ixx>
          <ixy>0.0</ixy>
          <ixz>0.0</ixz>
          <iyy>0.00026</iyy>
          <iyz>0.0</iyz>
          <izz>0.00052</izz>
        </inertia>
      </inertial>

      <collision name="collision">
        <pose>0 0.18 0.072 1.5707 0 0</pose>
        <geometry>
          <cylinder>
            <radius>0.072</radius>
            <length>0.04</length>
          </cylinder>
        </geometry>
        <surface>
          <friction>
            <ode>
              <mu>0.5</mu>
              <mu2>0.5</mu2>
            </ode>
          </friction>
          <contact>
            <ode>
              <kp>100000</kp>
              <kd>1</kd>
            </ode>
          </contact>
        </surface>
      </collision>

      <visual name="visual">
        <pose>0 0.18 0.072 1.5707 0 0</pose>
        <geometry>
          <cylinder>
            <radius>0.072</radius>
            <length>0.04</length>
          </cylinder>
        </geometry>
        <material>
          <script>
            <uri>file://media/materials/scripts/gazebo.material</uri>
            <name>Gazebo/Red</name>
          </script>
        </material>
      </visual>
    </link>

    <joint name="wheel_right_joint" type="revolute">
      <parent>base_link</parent>
      <child>wheel_right_link</child>
      <pose>0 -0.18 0.072 0 0 0</pose>
      <axis>
        <xyz>0 1 0</xyz>
      </axis>
    </joint>

    <link name="wheel_right_link">
      <inertial>
        <pose>0 -0.18 0.072 1.5707 0 0</pose>
        <mass>0.2</mass>
        <inertia>
          <ixx>0.00026</ixx>
          <ixy>0.0</ixy>
          <ixz>0.0</ixz>
          <iyy>0.00026</iyy>
          <iyz>0.0</iyz>
          <izz>0.00052</izz>
        </inertia>
      </inertial>

      <collision name="collision">
        <pose>0 -0.18 0.072 1.5707 0 0</pose>
        <geometry>
          <cylinder>
            <radius>0.072</radius>
            <length>0.04</length>
          </cylinder>
        </geometry>
        <surface>
          <friction>
            <ode>
              <mu>0.5</mu>
              <mu2>0.5</mu2>
            </ode>
          </friction>
          <contact>
            <ode>
              <kp>100000</kp>
              <kd>1</kd>
            </ode>
          </contact>
        </surface>
      </collision>

      <visual name="visual">
        <pose>0 -0.18 0.072 1.5707 0 0</pose>
        <geometry>
          <cylinder>
            <radius>0.072</radius>
            <length>0.04</length>
          </cylinder>
        </geometry>
        <material>
          <script>
            <uri>file://media/materials/scripts/gazebo.material</uri>
            <name>Gazebo/Red</name>
          </script>
        </material>
      </visual>
    </link>

    <joint name="caster_back_joint" type="fixed">
      <parent>base_link</parent>
      <child>caster_back_link</child>
      <pose>0 0 0 0 0 0</pose>
    </joint>

    <link name="caster_back_link">
      <inertial>
        <pose>-0.15 0 0.05 0 0 0</pose>
        <mass>0.1</mass>
        <inertia>
          <ixx>0.000001</ixx>
          <ixy>0.0</ixy>
          <ixz>0.0</ixz>
          <iyy>0.000001</iyy>
          <iyz>0.0</iyz>
          <izz>0.000001</izz>
        </inertia>
      </inertial>

      <collision name="collision">
        <pose>-0.15 0 0.05 0 0 0</pose>
        <geometry>
          <sphere>
            <radius>0.05</radius>
          </sphere>
        </geometry>
        <surface>
          <friction>
            <ode>
              <mu>0.01</mu>
              <mu2>0.01</mu2>
            </ode>
          </friction>
          <contact>
            <ode>
              <kp>100000</kp>
              <kd>1</kd>
            </ode>
          </contact>
        </surface>
      </collision>

      <visual name="visual">
        <pose>-0.15 0 0.05 0 0 0</pose>
        <geometry>
          <sphere>
            <radius>0.05</radius>
          </sphere>
        </geometry>
      </visual>
    </link>

    <plugin name="differential_drive_controller" filename="libgazebo_ros_diff_drive.so">
      <update_rate>30</update_rate>
      <left_joint>wheel_left_joint</left_joint>
      <right_joint>wheel_right_joint</right_joint>
      <wheel_separation>0.36</wheel_separation>
      <wheel_diameter>0.144</wheel_diameter>
      <max_wheel_torque>5.0</max_wheel_torque>
      <max_wheel_acceleration>30</max_wheel_acceleration>
      <publish_odom>true</publish_odom>
      <publish_odom_tf>true</publish_odom_tf>
      <publish_wheel_tf>false</publish_wheel_tf>
      <command_topic>cmd_vel</command_topic>
      <odometry_topic>odom</odometry_topic>
      <odometry_frame>odom</odometry_frame>
      <robot_base_frame>base_footprint</robot_base_frame>
    </plugin>

    <plugin name="turtlebot3_joint_state" filename="libgazebo_ros_joint_state_publisher.so">
      <ros>
        <remapping>~/out:=joint_states</remapping>
      </ros>
      <update_rate>30</update_rate>
      <joint_name>wheel_left_joint</joint_name>
      <joint_name>wheel_right_joint</joint_name>
    </plugin>      
  </model>
</sdf>
